WARNING 09-30 14:31:56 _custom_ops.py:18] Failed to import from vllm._C with ImportError('libcuda.so.1: cannot open shared object file: No such file or directory')
Namespace(backend='vllm', base_url='https://vgpu-test-1.service-inference.ai', host='localhost', port=8000, endpoint='/v1/completions', dataset=None, dataset_name='sharegpt', dataset_path='./ShareGPT_V3_unfiltered_cleaned_split.json', model='meta-llama/Meta-Llama-3-8B-Instruct', tokenizer=None, best_of=1, use_beam_search=False, num_prompts=40960, sharegpt_output_len=None, sonnet_input_len=550, sonnet_output_len=150, sonnet_prefix_len=200, random_input_len=1024, random_output_len=128, random_range_ratio=1.0, request_rate=1.0, seed=0, trust_remote_code=False, disable_tqdm=False, save_result=False, metadata=None, result_dir=None, result_filename=None, ignore_eos=False)
Starting initial single prompt test run...
Initial test run completed. Starting main benchmark run...
Traffic request rate: 1.0
