WARNING 10-09 18:53:28 _custom_ops.py:18] Failed to import from vllm._C with ImportError('libcuda.so.1: cannot open shared object file: No such file or directory')
Namespace(backend='vllm', base_url=None, host='216.81.245.85', port=30302, endpoint='/v1/completions', dataset=None, dataset_name='sharegpt', dataset_path='./ShareGPT_V3_unfiltered_cleaned_split.json', model='meta-llama/Meta-Llama-3-8B-Instruct', tokenizer=None, best_of=1, use_beam_search=False, num_prompts=10240, sharegpt_output_len=None, sonnet_input_len=550, sonnet_output_len=150, sonnet_prefix_len=200, random_input_len=1024, random_output_len=128, random_range_ratio=1.0, request_rate=1.5, seed=0, trust_remote_code=False, disable_tqdm=False, save_result=False, metadata=None, result_dir=None, result_filename=None, ignore_eos=False)
Starting initial single prompt test run...
